<?xml version="1.0" ?><testsuites errors="0" failures="1" name="test_calc" skipped="0" tests="3" time="0.010738"><testsuite errors="0" failures="1" name="test_calc.SingleFileTestScript" package="test_calc.SingleFileTestScript" skipped="0" tests="3"><testcase name="test_add" status="success" time="0.003691"/><testcase name="test_divide" status="fail" time="0.002969"><failure message="AssertionError: 50 != 4
">['Traceback (most recent call last):\n', '  File &quot;/usr/lib/python2.7/unittest/case.py&quot;, line 329, in run\n    testMethod()\n', '  File &quot;test_calc.py&quot;, line 38, in test_divide\n    self.assertEqual(calc.multiply(10, 5), 4)\n', '  File &quot;/usr/lib/python2.7/unittest/case.py&quot;, line 513, in assertEqual\n    assertion_func(first, second, msg=msg)\n', '  File &quot;/usr/lib/python2.7/unittest/case.py&quot;, line 506, in _baseAssertEqual\n    raise self.failureException(msg)\n', 'AssertionError: 50 != 4\n']</failure></testcase><testcase name="test_multiply" status="success" time="0.001752"/></testsuite></testsuites>